Workbook

Sheet format
A1: 股票代码 | B1: 公司名称 | C1: 报告名称 | D1: 总股本（亿） | E1: 分红（HKD） | F1: 营业收入（亿RMB） | G1: 营业成本（亿RMB） | H1: 营业利润（亿RMB） | I1: 净利润（亿RMB） | J1: 归母利润（亿RMB） | K1: 扣非利润（亿RMB） | L1: 销售费用（亿RMB） | M1: 管理费用（亿RMB） | N1: 研发费用（亿RMB） | O1: 融资成本（亿RMB） | P1: 货币资金（亿RMB） | Q1: 应收（亿RMB） | R1: 库存（亿RMB） | S1: 投资（亿RMB） | T1: 应付（亿RMB） | U1: 短期贷款（亿RMB） | V1: 长期贷款（亿RMB） | W1: 总资产（亿RMB） | X1: 净资产（亿RMB） | Y1: 非流动资产（亿RMB） | Z1: 流动负债（亿RMB） | AA1: 经营现金流净额（亿RMB） | AB1: 资本开支（亿RMB）
A2: 700 | B2: 腾讯控股 | C2: 2023年报 | D2: 93.42 | E2: 3.4 | F2: 6090 | G2: 3159 | H2: 1517 | I2: 1180 | J2: 1152 | K2: 1577 | L2: 342 | M2: 1035 | N2: 641 | O2: 127 | P2: =3621+208 -> 3829 | Q2: 466 | R2: 4.6 | S2: 6893 | T2: 1152 | U2: 477 | V2: 3094 | W2: 15800 | X2: 8737 | Y2: 10600 | Z2: 3522 | AA2: 2220 | AB2: 622
A3: 700 | B3: 腾讯控股 | C3: 2024年报 | D3: 91.79 | E3: 4.5 | F3: 6603 | G3: 3110 | H3: 2035 | I3: 1965 | J3: 1940 | K3: 2227 | L3: 364 | M3: 1148 | N3: 707 | O3: 120 | P3: 4760 | Q3: 482 | R3: 4.4 | S3: =6534+3389 -> 9923 | T3: 1273 | U3: 947 | V3: 2910 | W3: 17800 | X3: 10500 | Y3: 12800 | Z3: 3969 | AA3: 2585 | AB3: 960

Sheet Raw
B1: 报告名称 | C1: 港股股价 | D1: 人民币股价 | E1: 总股本 | F1: 净资产 | G1: 当期市值 | H1: PB | I1: 分红 | J1: 净资产增长率 | K1: 股息率 | L1: 资产收益 | M1: 扣非利润 | N1: 资产收益率 | O1: 归母利润 | P1: 扣非PE | Q1: 营业收入 | R1: 营业成本 | S1: 营业利润 | T1: 净利润 | U1: 归母利润 | V1: 归母/净利润 | W1: 扣非利润 | X1: 销售费用 | Y1: 管理费用 | Z1: 研发费用 | AA1: 融资成本 | AB1: 货币资金 | AC1: 应收 | AD1: 库存 | AE1: 投资 | AF1: 应付 | AG1: 合同负债变动（%） | AH1: 短期贷款 | AI1: 长期贷款 | AJ1: 总资产 | AK1: 净资产 | AL1: 非流动资产 | AM1: 流动负债 | AN1: 总资产-流动负债 | AO1: 经营现金流净额 | AP1: 资本开支 | AS1: 三年平均资本开支 | AT1: 三年经营现金流净额 | AW1: 三年净利润 | AZ1: 现金流/利润 | BA1: 平均现金流 | BB1: 平均自由现金流 | BC1: 净现金 | BD1: 净现金/资本开支 | BE1: 净现金/市值
A2: 港元/人民币汇率 | B2: =[1]正常估值!B2 -> 0.9152
A3: 腾讯控股 | B3: 2023年报 | C3: 304 | D3: =C3*$B$2 -> 278.2208 | E3: 93.42 | F3: 85.27 | G3: =D3*E3 -> 25991.387 | H3: =C3/F3 -> 3.565146 | I3: 3.4 | J3: 0.03 | K3: =I3/C3 -> 0.011184211 | L3: =I3+F3*J3 -> 5.9581 | M3: =W3/E3 -> 16.880754 | N3: =L3/F3 -> 0.069873343 | O3: =U3/E3 -> 12.331407 | P3: =D3*E3/W3 -> 16.481539 | Q3: 6090 | R3: 3159 | S3: 1517 | T3: 1180 | U3: 1152 | V3: =U3/T3 -> 0.97627119 | W3: 1577 | X3: 342 | Y3: 1035 | Z3: 641 | AA3: 127 | AB3: =3621+208 -> 3829 | AC3: 466 | AD3: 4.6 | AE3: 6893 | AF3: 1152 | AH3: 477 | AI3: 3094 | AJ3: 15800 | AK3: 8737 | AL3: 10600 | AM3: 3522 | AN3: =AJ3-AM3 -> 12278 | AO3: 2220 | AP3: 474 | AQ3: 509 | AR3: 622 | AS3: =AVERAGE(AP3:AR3) -> 535 | AT3: 1752 | AU3: 1461 | AV3: 2220 | AW3: 2248 | AX3: 1882 | AY3: 1152 | AZ3: =(AT3+AU3+AV3)/(AW3+AX3+AY3) -> 1.0285877 | BA3: =AVERAGE(AT3:AV3) -> 1811 | BB3: =BA3-AS3 -> 1276 | BC3: =AB3+AE3-AH3-AI3 -> 7151 | BD3: =BC3/AS3 -> 13.366355 | BE3: =BC3/G3 -> 0.2751296 | BF3: =A3 -> 腾讯控股
A4: 腾讯控股 | B4: 2024年报 | C4: 600 | D4: 667 | E4: 91.79 | F4: 105.5 | G4: =D4*E4 -> 61223.93 | H4: =C4/F4 -> 5.6872038 | I4: 4.5 | J4: =F4/F3-1 -> 0.23724639 | K4: =I4/C4 -> 0.0075 | L4: =I4+F4*J4 -> 29.529495 | M4: =W4/E4 -> 24.261902 | N4: =L4/F4 -> 0.27990042 | O4: =U4/E4 -> 21.1352 | P4: =D4*E4/W4 -> 27.491661 | Q4: 6603 | R4: 3110 | S4: 2035 | T4: 1965 | U4: 1940 | V4: =U4/T4 -> 0.98727735 | W4: 2227 | X4: 364 | Y4: 1148 | Z4: 707 | AA4: 120 | AB4: 4760 | AC4: 482 | AD4: 4.4 | AE4: =6534+3389 -> 9923 | AF4: 1273 | AH4: 947 | AI4: 2910 | AJ4: 17800 | AK4: 10500 | AL4: 12800 | AM4: 3969 | AN4: =AJ4-AM4 -> 13831 | AO4: 2585 | AP4: 960 | AQ4: 474 | AR4: 509 | AS4: =AVERAGE(AP4:AR4) -> 647.66667 | AT4: 1461 | AU4: 2220 | AV4: 2585 | AW4: 1882 | AX4: 1152 | AY4: 1941 | AZ4: =(AT4+AU4+AV4)/(AW4+AX4+AY4) -> 1.2594975 | BA4: 2850 | BB4: =BA4-AS4 -> 2202.3333 | BC4: =AB4+AE4-AH4-AI4 -> 10826 | BD4: =BC4/AS4 -> 16.715389 | BE4: =BC4/G4 -> 0.17682628 | BF4: =A4 -> 腾讯控股
A5: 阿里巴巴 | B5: 2024年报 | C5: 80 | D5: =C5*$B$2 -> 73.216 | E5: 193.45 | F5: 48.21 | G5: =D5*E5 -> 14163.635 | H5: =C5/F5 -> 1.6594068 | I5: =(0.125+0.0825)*7.8 -> 1.6185 | J5: 0.05 | K5: =I5/C5 -> 0.02023125 | L5: =I5+F5*J5 -> 4.029 | M5: =W5/E5 -> 4.1199276 | N5: =L5/F5 -> 0.083571873 | O5: =U5/E5 -> 4.1199276 | P5: =D5*E5/W5 -> 17.771186 | Q5: 9411 | R5: 5863 | S5: 1016 | T5: 713 | U5: 797 | V5: =U5/T5 -> 1.1178121 | W5: 797 | X5: 1151 | Y5: 636 | Z5: 523 | AA5: 79 | AB5: =2864+3229 -> 6093 | AC5: 306.86 | AD5: 0 | AE5: 4240 | AF5: 0 | AH5: 290 | AI5: 1418 | AJ5: 17600 | AK5: 11000 | AL5: 10100 | AM5: 4215 | AN5: =AJ5-AM5 -> 13385 | AO5: 1826 | AP5: 330 | AQ5: 533 | AR5: 432 | AS5: =AVERAGE(AP5:AR5) -> 431.66667 | AT5: 1826 | AU5: 1997 | AV5: 1428 | AW5: 713 | AX5: 656 | AY5: 471 | AZ5: =(AT5+AU5+AV5)/(AW5+AX5+AY5) -> 2.8538043 | BA5: =AVERAGE(AT5:AV5) -> 1750.3333 | BB5: =BA5-AS5 -> 1318.6667 | BC5: =AB5+AE5-AH5-AI5 -> 8625 | BD5: =BC5/AS5 -> 19.980695 | BE5: =BC5/G5 -> 0.60895384 | BF5: =A5 -> 阿里巴巴
A6: 阿里巴巴 | B6: 三季报 | C6: 153 | D6: =C6*$B$2 -> 140.0256 | E6: 190.9 | F6: 57.87 | G6: =D6*E6 -> 26730.887 | H6: =C6/F6 -> 2.6438569 | I6: 1.64 | J6: =F6/F5-1 -> 0.20037337 | K6: =I6/C6 -> 0.010718954 | L6: =I6+F6*J6 -> 13.235607 | M6: =W6/E6 -> 6.7836564 | N6: =L6/F6 -> 0.22871275 | O6: =U6/E6 -> 6.7836564 | P6: =D6*E6/W6 -> 20.641612 | Q6: 9963 | R6: 5983 | S6: 1555 | T6: 1260 | U6: 1295 | V6: =U6/T6 -> 1.0277778 | W6: 1295 | X6: 1440 | Y6: 506 | Z6: 572 | AA6: 96 | AB6: =1893+2826 -> 4719 | AC6: 500 | AD6: 0 | AE6: 5670 | AF6: 0 | AH6: 226 | AI6: 2081 | AJ6: 18000 | AK6: 10800 | AL6: 11300 | AM6: 4353 | AN6: =AJ6-AM6 -> 13647 | AO6: 1635 | AP6: 860 | AQ6: 330 | AR6: 533 | AS6: =AVERAGE(AP6:AR6) -> 574.33333 | AT6: 1635 | AU6: 1826 | AV6: 1997 | AW6: 1260 | AX6: 713 | AY6: 656 | AZ6: =(AT6+AU6+AV6)/(AW6+AX6+AY6) -> 2.0760746 | BA6: =AVERAGE(AT6:AV6) -> 1819.3333 | BB6: =BA6-AS6 -> 1245 | BC6: =AB6+AE6-AH6-AI6 -> 8082 | BD6: =BC6/AS6 -> 14.071967 | BE6: =BC6/G6 -> 0.30234687 | BF6: =A6 -> 阿里巴巴
A7: 联想集团 | B7: 2024年报 | C7: 7 | D7: =C7*$B$2 -> 6.4064 | E7: 124.05 | F7: =0.41*7.1 -> 2.911 | G7: =D7*E7 -> 794.71392 | H7: =C7/F7 -> 2.4046719 | I7: 0.385 | J7: 0 | K7: =I7/C7 -> 0.055 | L7: =I7+F7*J7 -> 0.385 | M7: =W7/E7 -> 0.081499395 | N7: =L7/F7 -> 0.13225696 | O7: =U7/E7 -> 0.081499395 | P7: =D7*E7/W7/7.3 -> 10.768044 | Q7: 568 | R7: 471 | S7: 13.9 | T7: 11 | U7: 10.11 | V7: =U7/T7 -> 0.91909091 | W7: 10.11 | X7: 33 | Y7: 24.9 | Z7: 20.28 | AA7: 7.73 | AB7: 37 | AC7: 81.5 | AD7: 67 | AE7: 17.68 | AF7: 105 | AH7: 0.5 | AI7: 35.7 | AJ7: 387 | AK7: 60.8 | AL7: 163 | AM7: 261 | AN7: =AJ7-AM7 -> 126 | AO7: 20.11 | AP7: 7.3 | AQ7: 11.2 | AR7: 10 | AS7: =AVERAGE(AP7:AR7) -> 9.5 | AT7: 20 | AU7: 28 | AV7: 41 | AW7: 11 | AX7: 16.8 | AY7: 21.5 | AZ7: =(AT7+AU7+AV7)/(AW7+AX7+AY7) -> 1.8052738 | BA7: =AVERAGE(AT7:AV7) -> 29.666667 | BB7: =BA7-AS7 -> 20.166667 | BC7: =AB7+AE7-AH7-AI7 -> 18.48 | BD7: =BC7/AS7 -> 1.9452632 | BE7: =BC7/G7 -> 0.023253651 | BF7: =A7 -> 联想集团
A8: 联想集团 | B8: 2025年报 | C8: 9.8 | D8: =C8*$B$2 -> 8.96896 | E8: 124.05 | F8: 3.96 | G8: =D8*E8 -> 1112.5995 | H8: =C8/F8 -> 2.4747475 | I8: 0.385 | J8: 0.0966 | K8: =I8/C8 -> 0.039285714 | L8: =I8+F8*J8 -> 0.767536 | M8: 1.03 | N8: =L8/F8 -> 0.19382222 | O8: =U8/E8*[1]正常估值!D2 -> 0.79356027 | P8: =G8/W8/[1]正常估值!D2 -> 11.302179 | Q8: 691 | R8: 580 | S8: 15.01 | T8: 14.62 | U8: 13.84 | V8: =U8/T8 -> 0.94664843 | W8: 13.84 | X8: 35.85 | Y8: 28.23 | Z8: 22.88 | AA8: 7.63 | AB8: 49 | AC8: 105.07 | AD8: 79 | AE8: 18.25 | AF8: 120 | AH8: 10.3 | AI8: 43.38 | AJ8: 442 | AK8: 66.6 | AL8: 161 | AM8: 300 | AN8: =AJ8-AM8 -> 142 | AO8: 11 | AP8: 6.66 | AQ8: 7.3 | AR8: 11.2 | AS8: =AVERAGE(AP8:AR8) -> 8.3866667 | AT8: 11 | AU8: 20 | AV8: 28 | AW8: 14.62 | AX8: 11 | AY8: 16.8 | AZ8: =(AT8+AU8+AV8)/(AW8+AX8+AY8) -> 1.3908534 | BA8: =AVERAGE(AT8:AV8) -> 19.666667 | BB8: =BA8-AS8 -> 11.28 | BC8: =AB8+AE8-AH8-AI8 -> 13.57 | BD8: =BC8/AS8 -> 1.6180445 | BE8: =BC8/G8 -> 0.012196662 | BF8: =A8 -> 联想集团
A9: 小米集团 | B9: 2023年报 | C9: 15 | D9: =C9*$B$2 -> 13.728 | E9: 249.55 | F9: 6.54 | G9: =D9*E9 -> 3425.8224 | H9: =C9/F9 -> 2.293578 | I9: 0 | J9: 0.09 | K9: =I9/C9 -> 0 | L9: =I9+F9*J9 -> 0.5886 | M9: =W9/E9 -> 0.70126227 | N9: =L9/F9 -> 0.09 | O9: =U9/E9 -> 0.70126227 | P9: =D9*E9/W9 -> 19.576128 | Q9: 2710 | R9: 2135 | S9: 220 | T9: 175 | U9: 175 | V9: =U9/T9 -> 1 | W9: 175 | X9: 192 | Y9: 51 | Z9: 191 | AA9: 15.56 | AB9: =912+213 -> 1125 | AC9: 123 | AD9: 444 | AE9: 675 | AF9: 621 | AH9: 62 | AI9: 217 | AJ9: 3243 | AK9: 1643 | AL9: 1252 | AM9: 1156 | AN9: =AJ9-AM9 -> 2087 | AO9: 413 | AP9: 63 | AQ9: 58 | AR9: 72 | AS9: =AVERAGE(AP9:AR9) -> 64.333333 | AT9: 98 | AU9: -44 | AV9: 413 | AW9: 193 | AX9: 25 | AY9: 175 | AZ9: =(AT9+AU9+AV9)/(AW9+AX9+AY9) -> 1.1882952 | BA9: =AVERAGE(AT9:AV9) -> 155.66667 | BB9: =BA9-AS9 -> 91.333333 | BC9: =AB9+AE9-AH9-AI9 -> 1521 | BD9: =BC9/AS9 -> 23.642487 | BE9: =BC9/G9 -> 0.44398098 | BF9: =A9 -> 小米集团
A10: 小米集团 | B10: 2024年报 | C10: 38 | D10: =C10*$B$2 -> 34.7776 | E10: 251.12 | F10: 7.52 | G10: =D10*E10 -> 8733.3509 | H10: =C10/F10 -> 5.0531915 | I10: 0 | J10: =F10/F9-1 -> 0.14984709 | K10: =I10/C10 -> 0 | L10: =I10+F10*J10 -> 1.1268502 | M10: =W10/E10 -> 0.9437719 | N10: =L10/F10 -> 0.14984709 | O10: =U10/E10 -> 0.9437719 | P10: =D10*E10/W10 -> 36.849582 | Q10: 3659 | R10: 2893 | S10: 279 | T10: 236 | U10: 237 | V10: =U10/T10 -> 1.0042373 | W10: 237 | X10: 254 | Y10: 56 | Z10: 241 | AA10: 2.12 | AB10: 1060 | AC10: 158 | AD10: 625 | AE10: 715 | AF10: 983 | AH10: 133 | AI10: 173 | AJ10: 4031 | AK10: 1892 | AL10: 1774 | AM10: 1754 | AN10: =AJ10-AM10 -> 2277 | AO10: 393 | AP10: 73 | AQ10: 63 | AR10: 58 | AS10: =AVERAGE(AP10:AR10) -> 64.666667 | AT10: 98 | AU10: -44 | AV10: 413 | AW10: 193 | AX10: 25 | AY10: 175 | AZ10: =(AT10+AU10+AV10)/(AW10+AX10+AY10) -> 1.1882952 | BA10: 400 | BB10: =BA10-AS10 -> 335.33333 | BC10: =AB10+AE10-AH10-AI10 -> 1469 | BD10: =BC10/AS10 -> 22.716495 | BE10: =BC10/G10 -> 0.16820577 | BF10: =A10 -> 小米集团
A11: 联邦制药 | B11: 2023年报 | C11: 8.6 | D11: =C11*$B$2 -> 7.87072 | E11: 18.17 | F11: 7.01 | G11: =D11*E11 -> 143.01098 | H11: =C11/F11 -> 1.2268188 | I11: 0.4 | J11: 0.17 | K11: =I11/C11 -> 0.046511628 | L11: =I11+F11*J11 -> 1.5917 | M11: =W11/E11 -> 1.4859659 | N11: =L11/F11 -> 0.22706134 | O11: =U11/E11 -> 1.4859659 | P11: =D11*E11/W11 -> 5.2967031 | Q11: 137 | R11: 74 | S11: 33.5 | T11: 27 | U11: 27 | V11: =U11/T11 -> 1 | W11: 27 | X11: 15.94 | Y11: 7.9 | Z11: 8.08 | AA11: 0.7 | AB11: 52.34 | AC11: 59 | AD11: 22 | AE11: 0.1 | AF11: 42 | AH11: 2 | AI11: 13 | AJ11: 210 | AK11: 127.5 | AL11: 72.3 | AM11: 66 | AN11: =AJ11-AM11 -> 144 | AO11: 24.39 | AP11: 8.2 | AQ11: 4.9 | AR11: 5.3 | AS11: =AVERAGE(AP11:AR11) -> 6.1333333 | AT11: 15.43 | AU11: 20.3 | AV11: 24.4 | AW11: 9.88 | AX11: 15.81 | AY11: 27 | AZ11: =(AT11+AU11+AV11)/(AW11+AX11+AY11) -> 1.1412033 | BA11: =AVERAGE(AT11:AV11) -> 20.043333 | BB11: =BA11-AS11 -> 13.91 | BC11: =AB11+AE11-AH11-AI11 -> 37.44 | BD11: =BC11/AS11 -> 6.1043478 | BE11: =BC11/G11 -> 0.26179808 | BF11: =A11 -> 联邦制药
A12: 联邦制药 | B12: 2024年报 | C12: 12.8 | D12: =C12*$B$2 -> 11.71456 | E12: 18.17 | F12: 7.92 | G12: =D12*E12 -> 212.85356 | H12: =C12/F12 -> 1.6161616 | I12: 0.56 | J12: =F12/F11-1 -> 0.12981455 | K12: =I12/C12 -> 0.04375 | L12: =I12+F12*J12 -> 1.5881312 | M12: =W12/E12 -> 1.4859659 | N12: =L12/F12 -> 0.20052162 | O12: =U12/E12 -> 1.4859659 | P12: =D12*E12/W12 -> 7.883465 | Q12: 137 | R12: 77 | S12: 33 | T12: 27 | U12: 27 | V12: =U12/T12 -> 1 | W12: 27 | X12: 14 | Y12: 8.9 | Z12: 9.86 | AA12: 0.3 | AB12: 74 | AC12: 57 | AD12: 24 | AE12: 0.1 | AF12: 42 | AH12: 8.35 | AI12: 23 | AJ12: 258 | AK12: 144 | AL12: 97.6 | AM12: 88 | AN12: =AJ12-AM12 -> 170 | AO12: 38 | AP12: 14.62 | AQ12: 8.2 | AR12: 4.9 | AS12: =AVERAGE(AP12:AR12) -> 9.24 | AT12: 15.43 | AU12: 20.3 | AV12: 24.4 | AW12: 9.88 | AX12: 15.81 | AY12: 27 | AZ12: =(AT12+AU12+AV12)/(AW12+AX12+AY12) -> 1.1412033 | BA12: =AVERAGE(AT12:AV12) -> 20.043333 | BB12: =BA12-AS12 -> 10.803333 | BC12: =AB12+AE12-AH12-AI12 -> 42.75 | BD12: =BC12/AS12 -> 4.6266234 | BE12: =BC12/G12 -> 0.20084231 | BF12: =A12 -> 联邦制药
A13: 中国海油 | B13: 2023年报 | C13: 16.96 | D13: =C13*$B$2 -> 15.521792 | E13: 475.67 | F13: 14.01 | G13: =D13*E13 -> 7383.2508 | H13: =C13/F13 -> 1.2105639 | I13: =0.66+0.6 -> 1.26 | J13: 0.14 | K13: =I13/C13 -> 0.074292453 | L13: =I13+F13*J13 -> 3.2214 | M13: =W13/E13 -> 2.6320769 | N13: =L13/F13 -> 0.22993576 | O13: =U13/E13 -> 2.6026447 | P13: =D13*E13/W13 -> 5.8971652 | Q13: 4166 | R13: 1078 | S13: 1710 | T13: 1241 | U13: 1238 | V13: =U13/T13 -> 0.99758259 | W13: 1252 | X13: 35 | Y13: 70 | Z13: 16 | AA13: 54 | AB13: 1948 | AC13: 370 | AD13: 65 | AE13: 646 | AF13: 614 | AH13: 241 | AI13: 961 | AJ13: 10100 | AK13: 6679 | AL13: 7553 | AM13: 1239 | AN13: =AJ13-AM13 -> 8861 | AO13: 2097 | AP13: 1209 | AQ13: 947 | AR13: 731 | AS13: =AVERAGE(AP13:AR13) -> 962.33333 | AT13: 1479 | AU13: 2056 | AV13: 2097 | AW13: 703 | AX13: 1417 | AY13: 1238 | AZ13: =(AT13+AU13+AV13)/(AW13+AX13+AY13) -> 1.6771888 | BA13: =AVERAGE(AT13:AV13) -> 1877.3333 | BB13: =BA13-AS13 -> 915 | BC13: =AB13+AE13-AH13-AI13 -> 1392 | BD13: =BC13/AS13 -> 1.4464842 | BE13: =BC13/G13 -> 0.18853484 | BF13: =A13 -> 中国海油
A14: 中国海油 | B14: 2024年报 | C14: 21 | D14: =C14*$B$2 -> 19.2192 | E14: 475.3 | F14: 15.73 | G14: =D14*E14 -> 9134.8858 | H14: =C14/F14 -> 1.3350286 | I14: 1.4 | J14: =F14/F13-1 -> 0.12276945 | K14: =I14/C14 -> 0.066666667 | L14: =I14+F14*J14 -> 3.3311635 | M14: =W14/E14 -> 3.078056 | N14: =L14/F14 -> 0.21177136 | O14: =U14/E14 -> 2.9013255 | P14: =D14*E14/W14 -> 6.2439411 | Q14: 4205 | R14: 786 | S14: 1881 | T14: 1380 | U14: 1379 | V14: =U14/T14 -> 0.99927536 | W14: 1463 | X14: 35 | Y14: 70 | Z14: 16 | AA14: 61 | AB14: =1542+458 -> 2000 | AC14: 337 | AD14: 181 | AE14: 570 | AF14: 597 | AH14: 224 | AI14: 695 | AJ14: 10600 | AK14: 7494 | AL14: 7917 | AM14: 1189 | AN14: =AJ14-AM14 -> 9411 | AO14: 2209 | AP14: 1234 | AQ14: 1209 | AR14: 947 | AS14: =AVERAGE(AP14:AR14) -> 1130 | AT14: 2056 | AU14: 2097 | AV14: 2209 | AW14: 1417 | AX14: 1238 | AY14: 1380 | AZ14: =(AT14+AU14+AV14)/(AW14+AX14+AY14) -> 1.5767038 | BA14: =AVERAGE(AT14:AV14) -> 2120.6667 | BB14: =BA14-AS14 -> 990.66667 | BC14: =AB14+AE14-AH14-AI14 -> 1651 | BD14: =BC14/AS14 -> 1.4610619 | BE14: =BC14/G14 -> 0.1807357 | BF14: =A14 -> 中国海油
A15: 中国移动 | B15: 2023年报 | C15: 62 | D15: =C15*$B$2 -> 56.7424 | E15: 214.14 | F15: 62.72 | G15: =D15*E15 -> 12150.818 | H15: =C15/F15 -> 0.98852041 | I15: 4.8 | J15: 0.03 | K15: =I15/C15 -> 0.077419355 | L15: =I15+F15*J15 -> 6.6816 | M15: =W15/E15 -> 5.5104137 | N15: =L15/F15 -> 0.10653061 | O15: =U15/E15 -> 6.1501821 | P15: =D15*E15/W15 -> 10.297303 | Q15: 10100 | R15: 4117 | S15: 1616 | T15: 1319 | U15: 1317 | V15: =U15/T15 -> 0.9984837 | W15: 1180 | X15: 525 | Y15: 560 | Z15: 287 | AA15: 37 | AB15: =1788+1560 -> 3348 | AC15: 561 | AD15: 120 | AE15: =1817+5+1856 -> 3678 | AF15: 3240 | AH15: 0 | AI15: 0 | AJ15: 19600 | AK15: 13100 | AL15: 14900 | AM15: 5586 | AN15: =AJ15-AM15 -> 14014 | AO15: 3037 | AP15: 1812 | AQ15: 1896 | AR15: 2027 | AS15: =AVERAGE(AP15:AR15) -> 1911.6667 | AT15: 3147 | AU15: 2807 | AV15: 3037 | AW15: 1160 | AX15: 1255 | AY15: 1318 | AZ15: =(AT15+AU15+AV15)/(AW15+AX15+AY15) -> 2.4085186 | BA15: =AVERAGE(AT15:AV15) -> 2997 | BB15: =BA15-AS15 -> 1085.3333 | BC15: =AB15+AE15-AH15-AI15 -> 7026 | BD15: =BC15/AS15 -> 3.6753269 | BE15: =BC15/G15 -> 0.5782327 | BF15: =A15 -> 中国移动
A16: 中国移动 | B16: 2024年报 | C16: 80 | D16: =C16*$B$2 -> 73.216 | E16: 215.27 | F16: 64.69 | G16: =D16*E16 -> 15761.208 | H16: =C16/F16 -> 1.2366672 | I16: =2.49+2.6 -> 5.09 | J16: =F16/F15-1 -> 0.031409439 | K16: =I16/C16 -> 0.063625 | L16: =I16+F16*J16 -> 7.1218766 | M16: =W16/E16 -> 5.6998188 | N16: =L16/F16 -> 0.11009239 | O16: =U16/E16 -> 6.4291355 | P16: =D16*E16/W16 -> 12.845321 | Q16: 10400 | R16: 4325 | S16: 1505 | T16: 1385 | U16: 1384 | V16: =U16/T16 -> 0.99927798 | W16: 1227 | X16: 546 | Y16: 569 | Z16: 281 | AA16: 33 | AB16: =2423+1532 -> 3955 | AC16: 768 | AD16: 112 | AE16: =1986+31+2094 -> 4111 | AF16: 3952 | AH16: 0 | AI16: 0 | AJ16: 20700 | AK16: 13600 | AL16: 15400 | AM16: 6330 | AN16: =AJ16-AM16 -> 14370 | AO16: 3157 | AP16: 1560 | AQ16: 1812 | AR16: 1896 | AS16: =AVERAGE(AP16:AR16) -> 1756 | AT16: 2807 | AU16: 3037 | AV16: 3157 | AW16: 1255 | AX16: 1318 | AY16: 1384 | AZ16: =(AT16+AU16+AV16)/(AW16+AX16+AY16) -> 2.2747031 | BA16: =AVERAGE(AT16:AV16) -> 3000.3333 | BB16: =BA16-AS16 -> 1244.3333 | BC16: =AB16+AE16-AH16-AI16 -> 8066 | BD16: =BC16/AS16 -> 4.5933941 | BE16: =BC16/G16 -> 0.51176279 | BF16: =A16 -> 中国移动
A17: 中国电信 | B17: 2023年报 | C17: 3.81 | D17: =C17*$B$2 -> 3.486912 | E17: 915.07 | F17: 4.84 | G17: =D17*E17 -> 3190.7686 | H17: =C17/F17 -> 0.78719008 | I17: 0.2332 | J17: 0.025 | K17: =I17/D17 -> 0.066878659 | L17: =I17+F17*J17 -> 0.3542 | M17: =W17/E17 -> 0.31363721 | N17: =L17/F17 -> 0.073181818 | O17: =U17/E17 -> 0.33221502 | P17: =D17*E17/W17 -> 11.117661 | Q17: 5135 | R17: 0 | S17: 371 | T17: 304 | U17: 304 | V17: =U17/T17 -> 1 | W17: 287 | X17: 668 | Y17: 357 | Z17: 131 | AA17: 25.45 | AB17: 918.5 | AC17: 322 | AD17: 34 | AE17: 432 | AF17: 1459 | AH17: 28 | AI17: 51 | AJ17: 8358 | AK17: 4472 | AL17: 6628 | AM17: 3108 | AN17: =AJ17-AM17 -> 5250 | AO17: 1386 | AP17: 902 | AQ17: 915 | AR17: 852 | AS17: =AVERAGE(AP17:AR17) -> 889.66667 | AT17: 1375 | AU17: 1364 | AV17: 1375 | AW17: 259 | AX17: 276 | AY17: 304 | AZ17: =(AT17+AU17+AV17)/(AW17+AX17+AY17) -> 4.9034565 | BA17: =AVERAGE(AT17:AV17) -> 1371.3333 | BB17: =BA17-AS17 -> 481.66667 | BC17: =AB17+AE17-AH17-AI17 -> 1271.5 | BD17: =BC17/AS17 -> 1.429187 | BE17: =BC17/G17 -> 0.39849333 | BF17: =A17 -> 中国电信
A18: 中国电信 | B18: 2024年报 | C18: 6.25 | D18: =C18*$B$2 -> 5.72 | E18: 915.07 | F18: 4.94 | G18: =D18*E18 -> 5234.2004 | H18: =C18/F18 -> 1.2651822 | I18: 0.2598 | J18: =F18/F17-1 -> 0.020661157 | K18: =I18/D18 -> 0.04541958 | L18: =I18+F18*J18 -> 0.36186612 | M18: =W18/E18 -> 0.33549346 | N18: =L18/F18 -> 0.07325225 | O18: =U18/E18 -> 0.36062815 | P18: =D18*E18/W18 -> 17.049513 | Q18: 5294 | R18: 0 | S18: 420 | T18: 330 | U18: 330 | V18: =U18/T18 -> 1 | W18: 307 | X18: 667 | Y18: 371 | Z18: 145 | AA18: 24 | AB18: 1020 | AC18: 429 | AD18: 32 | AE18: 442 | AF18: 1605 | AH18: 28 | AI18: 75 | AJ18: 8666 | AK18: 4565 | AL18: 6628 | AM18: 3108 | AN18: =AJ18-AM18 -> 5558 | AO18: 1452 | AP18: 903 | AQ18: 902 | AR18: 915 | AS18: =AVERAGE(AP18:AR18) -> 906.66667 | AT18: 1372 | AU18: 1386 | AV18: 1452 | AW18: 276 | AX18: 304 | AY18: 330 | AZ18: =(AT18+AU18+AV18)/(AW18+AX18+AY18) -> 4.6263736 | BA18: =AVERAGE(AT18:AV18) -> 1403.3333 | BB18: =BA18-AS18 -> 496.66667 | BC18: =AB18+AE18-AH18-AI18 -> 1359 | BD18: =BC18/AS18 -> 1.4988971 | BE18: =BC18/G18 -> 0.25963851 | BF18: =A18 -> 中国电信
A19: 中国联通 | B19: 2023年报 | C19: 5.26 | D19: =C19*$B$2 -> 4.813952 | E19: 305.98 | F19: 12.62 | G19: =D19*E19 -> 1472.973 | H19: =C19/F19 -> 0.41679873 | I19: 0.3366 | J19: 0.025 | K19: =I19/D19 -> 0.069921761 | L19: =I19+F19*J19 -> 0.6521 | M19: =W19/E19 -> 0.61115106 | N19: =L19/F19 -> 0.051671949 | O19: =U19/E19 -> 0.61115106 | P19: =D19*E19/W19 -> 7.8768611 | Q19: 3726 | R19: 347 | S19: 186 | T19: 189 | U19: 187 | V19: =U19/T19 -> 0.98941799 | W19: 187 | X19: 600 | Y19: 1590 | Z19: 0 | AA19: 20 | AB19: =588+244 -> 832 | AC19: 387 | AD19: 22 | AE19: 596 | AF19: 1676 | AH19: 137 | AI19: 319 | AJ19: 6610 | AK19: 3539 | AL19: 5048 | AM19: 2603 | AN19: =AJ19-AM19 -> 4007 | AO19: 1005 | AP19: 793 | AQ19: 725 | AR19: 720 | AS19: =AVERAGE(AP19:AR19) -> 746 | AT19: 1106 | AU19: 1005 | AV19: 1023 | AW19: 144 | AX19: 167 | AY19: 187 | AZ19: =(AT19+AU19+AV19)/(AW19+AX19+AY19) -> 6.2931727 | BA19: =AVERAGE(AT19:AV19) -> 1044.6667 | BB19: =BA19-AS19 -> 298.66667 | BC19: =AB19+AE19-AH19-AI19 -> 972 | BD19: =BC19/AS19 -> 1.3029491 | BE19: =BC19/G19 -> 0.65988988 | BF19: =A19 -> 中国联通
A20: 中国联通 | B20: 2024年报 | C20: 10.2 | D20: =C20*$B$2 -> 9.33504 | E20: 305.98 | F20: 13.1 | G20: =D20*E20 -> 2856.3355 | H20: =C20/F20 -> 0.77862595 | I20: 0.411 | J20: =F20/F19-1 -> 0.038034865 | K20: =I20/D20 -> 0.044027664 | L20: =I20+F20*J20 -> 0.90925674 | M20: =W20/E20 -> 0.67324662 | N20: =L20/F20 -> 0.069408911 | O20: =U20/E20 -> 0.67324662 | P20: =D20*E20/W20 -> 13.865707 | Q20: 3896 | R20: 425 | S20: 212 | T20: 207 | U20: 206 | V20: =U20/T20 -> 0.99516908 | W20: 206 | X20: 643 | Y20: 1595 | Z20: 0 | AA20: 17.8 | AB20: 638 | AC20: 537 | AD20: 25 | AE20: 612 | AF20: 1687 | AH20: 144 | AI20: 254 | AJ20: 6712 | AK20: 3635 | AL20: 5140 | AM20: 2659 | AN20: =AJ20-AM20 -> 4053 | AO20: 1005 | AP20: 793 | AQ20: 725 | AR20: 720 | AS20: =AVERAGE(AP20:AR20) -> 746 | AT20: 1106 | AU20: 1005 | AV20: 1023 | AW20: 144 | AX20: 167 | AY20: 187 | AZ20: =(AT20+AU20+AV20)/(AW20+AX20+AY20) -> 6.2931727 | BA20: =AVERAGE(AT20:AV20) -> 1044.6667 | BB20: =BA20-AS20 -> 298.66667 | BC20: =AB20+AE20-AH20-AI20 -> 852 | BD20: =BC20/AS20 -> 1.1420912 | BE20: =BC20/G20 -> 0.29828428 | BF20: =A20 -> 中国联通
A21: 快手 | B21: 2023年报 | C21: 50 | D21: =C21*$B$2 -> 45.76 | E21: 43.39 | F21: 11.29 | G21: =D21*E21 -> 1985.5264 | H21: =C21/F21 -> 4.428698 | I21: 0 | J21: 0.03 | K21: =I21/C21 -> 0 | L21: =I21+F21*J21 -> 0.3387 | M21: =W21/E21 -> 1.4749942 | N21: =L21/F21 -> 0.03 | O21: =U21/E21 -> 1.4749942 | P21: =D21*E21/W21 -> 31.02385 | Q21: 1135 | R21: 561 | S21: 69 | T21: 64 | U21: 64 | V21: =U21/T21 -> 1 | W21: 64 | X21: 365 | Y21: 35 | Z21: 123 | AA21: 5.77 | AB21: 490 | AC21: 65 | AD21: 0 | AE21: 57 | AF21: 236 | AH21: 33 | AI21: 84 | AJ21: 1063 | AK21: 490 | AL21: 459 | AM21: 488 | AN21: =AJ21-AM21 -> 575 | AO21: 208 | AP21: 49 | AQ21: 46 | AR21: 78 | AS21: =AVERAGE(AP21:AR21) -> 57.666667 | AT21: -55 | AU21: 8 | AV21: 208 | AW21: -780 | AX21: -137 | AY21: 64 | AZ21: =(AT21+AU21+AV21)/(AW21+AX21+AY21) -> -0.1887456 | BA21: =AVERAGE(AT21:AV21) -> 53.666667 | BB21: =BA21-AS21 -> -4 | BC21: =AB21+AE21-AH21-AI21 -> 430 | BD21: =BC21/AS21 -> 7.4566474 | BE21: =BC21/G21 -> 0.21656725 | BF21: =A21 -> 快手
A22: 快手 | B22: 2024年报 | C22: 64 | D22: =C22*$B$2 -> 58.5728 | E22: 43.04 | F22: 14.44 | G22: =D22*E22 -> 2520.9733 | H22: =C22/F22 -> 4.432133 | I22: 0 | J22: =F22/F21-1 -> 0.27900797 | K22: =I22/C22 -> 0 | L22: =I22+F22*J22 -> 4.0288751 | M22: =W22/E22 -> 3.5548327 | N22: =L22/F22 -> 0.27900797 | O22: =U22/E22 -> 3.5548327 | P22: =D22*E22/W22 -> 16.47695 | Q22: 1269 | R22: 576 | S22: 154 | T22: 153 | U22: 153 | V22: =U22/T22 -> 1 | W22: 153 | X22: 411 | Y22: 30 | Z22: 122 | AA22: 8.35 | AB22: =243+273 -> 516 | AC22: 67 | AD22: 0 | AE22: 247 | AF22: 275 | AH22: 37 | AI22: 179 | AJ22: 1399 | AK22: 620 | AL22: 770 | AM22: 598 | AN22: =AJ22-AM22 -> 801 | AO22: 298 | AP22: 81 | AQ22: 49 | AR22: 46 | AS22: =AVERAGE(AP22:AR22) -> 58.666667 | AT22: 8 | AU22: 208 | AV22: 299 | AW22: -137 | AX22: 64 | AY22: 153 | AZ22: =(AT22+AU22+AV22)/(AW22+AX22+AY22) -> 6.4375 | BA22: =AVERAGE(AT22:AV22) -> 171.66667 | BB22: =BA22-AS22 -> 113 | BC22: =AB22+AE22-AH22-AI22 -> 547 | BD22: =BC22/AS22 -> 9.3238636 | BE22: =BC22/G22 -> 0.21697969 | BF22: =A22 -> 快手
A23: 美团 | B23: 2023年报 | C23: 91.4 | D23: =C23*$B$2 -> 83.64928 | E23: 62.35 | F23: 24.34 | G23: =D23*E23 -> 5215.5326 | H23: =C23/F23 -> 3.7551356 | I23: 0 | J23: 0.1 | K23: =I23/C23 -> 0 | L23: =I23+F23*J23 -> 2.434 | M23: =W23/E23 -> 2.2293504 | N23: =L23/F23 -> 0.1 | O23: =U23/E23 -> 2.2293504 | P23: =D23*E23/W23 -> 37.521817 | Q23: 2767 | R23: 1796 | S23: 128 | T23: 139 | U23: 139 | V23: =U23/T23 -> 1 | W23: 139 | X23: 586 | Y23: 94 | Z23: 212 | AA23: 14.25 | AB23: =527+1118 -> 1645 | AC23: 27 | AD23: 13 | AE23: 476 | AF23: 230 | AH23: 218 | AI23: 388 | AJ23: 2930 | AK23: 1520 | AL23: 1099 | AM23: 1009 | AN23: =AJ23-AM23 -> 1921 | AO23: 405 | AP23: 69 | AQ23: 57 | AR23: 90 | AS23: =AVERAGE(AP23:AR23) -> 72 | AT23: -40 | AU23: 114 | AV23: 405 | AW23: -235 | AX23: -67 | AY23: 138 | AZ23: =(AT23+AU23+AV23)/(AW23+AX23+AY23) -> -2.9207317 | BA23: =AVERAGE(AT23:AV23) -> 159.66667 | BB23: =BA23-AS23 -> 87.666667 | BC23: =AB23+AE23-AH23-AI23 -> 1515 | BD23: =BC23/AS23 -> 21.041667 | BE23: =BC23/G23 -> 0.29047848 | BF23: =A23 -> 美团
A24: 美团 | B24: 2024年报 | C24: 104 | D24: =C24*$B$2 -> 95.1808 | E24: 61.11 | F24: 33 | G24: =D24*E24 -> 5816.4987 | H24: =C24/F24 -> 3.1515152 | I24: 0 | J24: 0.17 | K24: =I24/C24 -> 0 | L24: =I24+F24*J24 -> 5.61 | M24: =W24/E24 -> 5.8582883 | N24: =L24/F24 -> 0.17 | O24: =U24/E24 -> 5.8582883 | P24: =D24*E24/W24 -> 16.247203 | Q24: 3376 | R24: 2078 | S24: 368 | T24: 358 | U24: 358 | V24: =U24/T24 -> 1 | W24: 358 | X24: 640 | Y24: 109 | Z24: 210 | AA24: 13.37 | AB24: 1890 | AC24: 31 | AD24: 25 | AE24: 434 | AF24: 456 | AH24: 28 | AI24: 318 | AJ24: 3301 | AK24: 1842 | AL24: 1128 | AM24: 1124 | AN24: =AJ24-AM24 -> 2177 | AO24: 571 | AP24: 110 | AQ24: 69 | AR24: 57 | AS24: =AVERAGE(AP24:AR24) -> 78.666667 | AT24: 114 | AU24: 405 | AV24: 571 | AW24: 358 | AX24: 138 | AY24: -67 | AZ24: =(AT24+AU24+AV24)/(AW24+AX24+AY24) -> 2.5407925 | BA24: =AVERAGE(AT24:AV24) -> 363.33333 | BB24: =BA24-AS24 -> 284.66667 | BC24: =AB24+AE24-AH24-AI24 -> 1978 | BD24: =BC24/AS24 -> 25.144068 | BE24: =BC24/G24 -> 0.34006713 | BF24: =A24 -> 美团
A25: 携程 | B25: 2024年报 | C25: 547 | D25: =C25*$B$2 -> 500.6144 | E25: 6.54 | F25: 247.7 | G25: =D25*E25 -> 3274.0182 | H25: =C25/F25 -> 2.2083165 | I25: 2.333 | J25: 0.15 | K25: =I25/C25 -> 0.0042650823 | L25: =I25+F25*J25 -> 39.488 | M25: =W25/E25 -> 26.146789 | N25: =L25/F25 -> 0.15941865 | O25: =U25/E25 -> 26.146789 | P25: =D25*E25/W25 -> 19.146305 | Q25: 534 | R25: 101 | S25: 170 | T25: 172 | U25: 171 | V25: =U25/T25 -> 0.99418605 | W25: 171 | X25: 119 | Y25: 41 | Z25: 131 | AA25: 17.4 | AB25: 796 | AC25: 125 | AD25: 0 | AE25: 472 | AF25: 166 | AH25: 194 | AI25: 207 | AJ25: 2426 | AK25: 1435 | AL25: 1305 | AM25: 740 | AN25: =AJ25-AM25 -> 1686 | AO25: 196 | AP25: 6 | AQ25: 6 | AR25: 5 | AS25: =AVERAGE(AP25:AR25) -> 5.6666667 | AT25: 26 | AU25: 220 | AV25: 196 | AW25: 172 | AX25: 100 | AY25: 14 | AZ25: =(AT25+AU25+AV25)/(AW25+AX25+AY25) -> 1.5454545 | BA25: =AVERAGE(AT25:AV25) -> 147.33333 | BB25: =BA25-AS25 -> 141.66667 | BC25: =AB25+AE25-AH25-AI25 -> 867 | BD25: =BC25/AS25 -> 153 | BE25: =BC25/G25 -> 0.26481221 | BF25: =A25 -> 携程
A26: 百度 | B26: 2023年报 | C26: 100 | D26: =C26*$B$2 -> 91.52 | E26: 29.03 | F26: 83.94 | G26: =D26*E26 -> 2656.8256 | H26: =C26/F26 -> 1.1913271 | I26: 0 | J26: 0.05 | K26: =I26/C26 -> 0 | L26: =I26+F26*J26 -> 4.197 | M26: =W26/E26 -> 6.2004823 | N26: =L26/F26 -> 0.05 | O26: =U26/E26 -> 6.9927661 | P26: =D26*E26/W26 -> 14.760142 | Q26: 1346 | R26: 650 | S26: 290 | T26: 215 | U26: 203 | V26: =U26/T26 -> 0.94418605 | W26: 180 | X26: 0 | Y26: 0 | Z26: 242 | AA26: 32 | AB26: =347+1687 -> 2034 | AC26: 108 | AE26: 726 | AF26: 60 | AH26: 191 | AI26: 624 | AJ26: 4068 | AK26: 2531 | AL26: 1765 | AM26: 765 | AN26: =AJ26-AM26 -> 3303 | AO26: 366 | AP26: 112 | AQ26: 83 | AR26: 109 | AS26: =AVERAGE(AP26:AR26) -> 101.33333 | AT26: 201 | AU26: 262 | AV26: 366 | AW26: 215 | AX26: 75 | AY26: 76 | AZ26: =(AT26+AU26+AV26)/(AW26+AX26+AY26) -> 2.2650273 | BA26: =AVERAGE(AT26:AV26) -> 276.33333 | BB26: =BA26-AS26 -> 175 | BC26: =AB26+AE26-AH26-AI26 -> 1945 | BD26: =BC26/AS26 -> 19.194079 | BE26: =BC26/G26 -> 0.73207666 | BF26: =A26 -> 百度
A27: 百度 | B27: 2024年报 | C27: 117 | D27: =C27*$B$2 -> 107.0784 | E27: 27.5 | F27: 109.68 | G27: =D27*E27 -> 2944.656 | H27: =C27/F27 -> 1.0667396 | I27: 0 | J27: 0.1365 | K27: =I27/C27 -> 0 | L27: =I27+F27*J27 -> 14.97132 | M27: =W27/E27 -> 7.6363636 | N27: =L27/F27 -> 0.1365 | O27: =U27/E27 -> 8.6181818 | P27: =D27*E27/W27 -> 14.022171 | Q27: 1331 | R27: 661 | S27: 293 | T27: 242 | U27: 237 | V27: =U27/T27 -> 0.97933884 | W27: 210 | X27: 0 | Y27: 0 | Z27: 221 | AA27: 28 | AB27: 1242 | AC27: 116 | AD27: 0 | AE27: 1552 | AF27: 47 | AH27: 270 | AI27: 137 | AJ27: 4505 | AK27: 2852 | AL27: 2934 | AM27: 851 | AN27: =AJ27-AM27 -> 3654 | AO27: 212 | AP27: 86 | AQ27: 112 | AR27: 83 | AS27: =AVERAGE(AP27:AR27) -> 93.666667 | AT27: 212 | AU27: 366 | AV27: 262 | AW27: 242 | AX27: 215 | AY27: 75 | AZ27: =(AT27+AU27+AV27)/(AW27+AX27+AY27) -> 1.5789474 | BA27: =AVERAGE(AT27:AV27) -> 280 | BB27: =BA27-AS27 -> 186.33333 | BC27: =AB27+AE27-AH27-AI27 -> 2387 | BD27: =BC27/AS27 -> 25.483986 | BE27: =BC27/G27 -> 0.810621 | BF27: =A27 -> 百度
A28: 拼多多 | B28: 2024年报 | D28: =120*[1]正常估值!D2 -> 853.536 | E28: =G28/D28 -> 14.210667 | F28: =35.85*[1]正常估值!D2 -> 254.99388 | G28: =1705.28*[1]正常估值!D2 -> 12129.316 | H28: =D28/F28 -> 3.3472803 | I28: 0 | J28: 0.5 | K28: =I28/D28 -> 0 | L28: =I28+F28*J28 -> 127.49694 | M28: =W28/E28 -> 79.095515 | N28: =L28/F28 -> 0.5 | O28: =U28/E28 -> 79.095515 | P28: =D28*E28/W28 -> 10.791206 | Q28: 3938 | R28: 1539 | S28: 1084 | T28: 1124 | U28: 1124 | V28: =U28/T28 -> 1 | W28: 1124 | X28: 1189 | Y28: 0 | Z28: 127 | AA28: 0 | AB28: 3316 | AC28: 37 | AD28: 0 | AE28: 0 | AF28: 0 | AH28: 53 | AI28: 0 | AJ28: 5050 | AK28: 3133 | AL28: 894 | AM28: 1884 | AN28: =AJ28-AM28 -> 3166 | AO28: 1219 | AP28: 10 | AQ28: 6 | AR28: 6 | AS28: =AVERAGE(AP28:AR28) -> 7.3333333 | AT28: 485 | AU28: 941 | AV28: 1219 | AW28: 1124 | AX28: 600 | AY28: 315 | AZ28: =(AT28+AU28+AV28)/(AW28+AX28+AY28) -> 1.2972045 | BA28: =AVERAGE(AT28:AV28) -> 881.66667 | BB28: =BA28-AS28 -> 874.33333 | BC28: =AB28+AE28-AH28-AI28 -> 3263 | BD28: =BC28/AS28 -> 444.95455 | BE28: =BC28/G28 -> 0.26901765 | BF28: =A28 -> 拼多多
A29: 华润啤酒 | B29: 2023年报 | C29: 23.8 | D29: =C29*$B$2 -> 21.78176 | E29: 32.44 | F29: 10.25 | G29: =D29*E29 -> 706.60029 | H29: =C29/F29 -> 2.3219512 | I29: =(0.349+0.287)/B2 -> 0.69493007 | J29: 0.1 | K29: =I29/C29 -> 0.029198742 | L29: =I29+F29*J29 -> 1.7199301 | M29: =W29/E29 -> 1.6029593 | N29: =L29/F29 -> 0.16779806 | O29: =U29/E29 -> 1.6029593 | P29: =D29*E29/W29 -> 13.588467 | Q29: 389 | R29: 228 | S29: 71 | T29: 52 | U29: 52 | V29: =U29/T29 -> 1 | W29: 52 | X29: 81 | Y29: 34 | Z29: 0 | AA29: 2.44 | AB29: 55 | AE29: 52 | AH29: 10 | AI29: 43 | AJ29: 715 | AK29: 342 | AL29: 537 | AM29: 261 | AN29: =AJ29-AM29 -> 454 | AO29: 42 | AP29: 25 | AQ29: 17 | AR29: 15 | AS29: =AVERAGE(AP29:AR29) -> 19 | AT29: 50 | AU29: 68 | AV29: 42 | AW29: 46 | AX29: 43 | AY29: 52 | AZ29: =(AT29+AU29+AV29)/(AW29+AX29+AY29) -> 1.1347518 | BA29: =AVERAGE(AT29:AV29) -> 53.333333 | BB29: =BA29-AS29 -> 34.333333 | BC29: =AB29+AE29-AH29-AI29 -> 54 | BD29: =BC29/AS29 -> 2.8421053 | BE29: =BC29/G29 -> 0.076422272 | BF29: =A29 -> 华润啤酒
A30: 青岛啤酒 | B30: 2023年报 | C30: 50 | D30: =C30*$B$2 -> 45.76 | E30: 13.64 | F30: 20.8 | G30: =D30*E30 -> 624.1664 | H30: =C30/F30 -> 2.4038462 | I30: =2/B2 -> 2.1853147 | J30: 0.09 | K30: =I30/C30 -> 0.043706294 | L30: =I30+F30*J30 -> 4.0573147 | M30: =W30/E30 -> 2.71261 | N30: =L30/F30 -> 0.19506321 | O30: =U30/E30 -> 3.1304985 | P30: =D30*E30/W30 -> 16.869362 | Q30: 339 | R30: 232 | S30: 55 | T30: 43.5 | U30: 42.7 | V30: =U30/T30 -> 0.9816092 | W30: 37 | X30: 47 | Y30: 15.2 | Z30: 1 | AA30: 0.5 | AB30: 213 | AC30: 1 | AD30: 35 | AE30: 3.7 | AF30: 31.5 | AH30: 0 | AI30: 0.6 | AJ30: 493 | AK30: 283 | AL30: 196 | AM30: 169 | AN30: =AJ30-AM30 -> 324 | AO30: 28 | AP30: 16.2 | AQ30: 17.8 | AR30: 16.4 | AS30: =AVERAGE(AP30:AR30) -> 16.8 | AT30: 60 | AU30: 49 | AV30: 28 | AW30: 32 | AX30: 37 | AY30: 43 | AZ30: =(AT30+AU30+AV30)/(AW30+AX30+AY30) -> 1.2232143 | BA30: =AVERAGE(AT30:AV30) -> 45.666667 | BB30: =BA30-AS30 -> 28.866667 | BC30: =AB30+AE30-AH30-AI30 -> 216.1 | BD30: =BC30/AS30 -> 12.863095 | BE30: =BC30/G30 -> 0.34622178 | BF30: =A30 -> 青岛啤酒
A31: 青岛啤酒 | B31: 2024年报 | C31: 53 | D31: =C31*$B$2 -> 48.5056 | E31: 13.64 | F31: 21.3 | G31: =D31*E31 -> 661.61638 | H31: =C31/F31 -> 2.4882629 | I31: 2.113 | J31: =F31/F30-1 -> 0.024038462 | K31: =I31/C31 -> 0.039867925 | L31: =I31+F31*J31 -> 2.6250192 | M31: =W31/E31 -> 3.1891496 | N31: =L31/F31 -> 0.12324034 | O31: =U31/E31 -> 3.1891496 | P31: =D31*E31/W31 -> 15.209572 | Q31: 321 | R31: 215 | S31: 58 | T31: 44.9 | U31: 43.5 | V31: =U31/T31 -> 0.9688196 | W31: 43.5 | X31: 46 | Y31: 14 | Z31: 1 | AA31: 0.5 | AB31: 200 | AC31: 1 | AD31: 36 | AE31: 3.9 | AF31: 32.7 | AH31: 0 | AI31: 0.7 | AJ31: 514 | AK31: 299 | AL31: 262 | AM31: 175 | AN31: =AJ31-AM31 -> 339 | AO31: 28 | AP31: 21.4 | AQ31: 16.2 | AR31: 17.8 | AS31: =AVERAGE(AP31:AR31) -> 18.466667 | AT31: 60 | AU31: 49 | AV31: 28 | AW31: 32 | AX31: 37 | AY31: 43 | AZ31: =(AT31+AU31+AV31)/(AW31+AX31+AY31) -> 1.2232143 | BA31: =AVERAGE(AT31:AV31) -> 45.666667 | BB31: =BA31-AS31 -> 27.2 | BC31: =AB31+AE31-AH31-AI31 -> 203.2 | BD31: =BC31/AS31 -> 11.00361 | BE31: =BC31/G31 -> 0.30712661 | BF31: =A31 -> 青岛啤酒
A32: 百威亚太 | B32: 2024年报 | C32: 8.4 | D32: =C32*$B$2 -> 7.68768 | E32: 132.43 | F32: =6.1*B2 -> 5.58272 | G32: =D32*E32 -> 1018.0795 | H32: =C32/F32 -> 1.5046429 | I32: 0.444 | J32: -0.05 | K32: =I32/C32 -> 0.052857143 | L32: =I32+F32*J32 -> 0.164864 | M32: =W32/E32 -> 0.054821415 | N32: =L32/F32 -> 0.029531125 | O32: =U32/E32 -> 0.054821415 | P32: =D32*E32/W32 -> 140.23133 | Q32: 62.5 | R32: 31 | S32: 10.86 | T32: 7.5 | U32: 7.26 | V32: =U32/T32 -> 0.968 | W32: 7.26 | X32: 16.25 | Y32: 4.77 | Z32: 0 | AA32: 0.35 | AB32: 29.44 | AC32: 3.6 | AD32: 3.76 | AE32: 5.04 | AF32: 16.33 | AH32: 1.36 | AI32: 0.7 | AJ32: 147.8 | AK32: 102.4 | AL32: 109.5 | AM32: 39.33 | AN32: =AJ32-AM32 -> 108.47 | AO32: 11.34 | AP32: 3.8 | AQ32: 5 | AR32: 4.94 | AS32: =AVERAGE(AP32:AR32) -> 4.58 | AT32: 15.77 | AU32: 18.11 | AV32: 11.34 | AW32: 7.5 | AX32: 8.8 | AY32: 9.5 | AZ32: =(AT32+AU32+AV32)/(AW32+AX32+AY32) -> 1.7527132 | BA32: =AVERAGE(AT32:AV32) -> 15.073333 | BB32: =BA32-AS32 -> 10.493333 | BC32: =AB32+AE32-AH32-AI32 -> 32.42 | BD32: =BC32/AS32 -> 7.0786026 | BE32: =BC32/G32 -> 0.031844273 | BF32: =A32 -> 百威亚太
A33: 蒙牛乳业 | B33: 2023年报 | C33: 17.12 | D33: =C33*$B$2 -> 15.668224 | E33: 39.35 | F33: 11.26 | G33: =D33*E33 -> 616.54461 | H33: =C33/F33 -> 1.5204263 | I33: 0.489 | J33: 0.1 | K33: =I33/C33 -> 0.028563084 | L33: =I33+F33*J33 -> 1.615 | M33: =W33/E33 -> 1.2198221 | N33: =L33/F33 -> 0.14342806 | O33: =U33/E33 -> 1.2198221 | P33: =D33*E33/W33 -> 12.844679 | Q33: 986 | R33: 620 | S33: 62 | T33: 49 | U33: 48 | V33: =U33/T33 -> 0.97959184 | W33: 48 | X33: 252 | Y33: 47 | Z33: 0 | AA33: 15.7 | AB33: 213 | AC33: 37 | AD33: 61 | AE33: 309 | AF33: 95 | AH33: 98 | AI33: 276 | AJ33: 1152 | AK33: 443 | AL33: 811 | AM33: 326 | AN33: =AJ33-AM33 -> 826 | AO33: 83 | AP33: 39 | AQ33: 49 | AR33: 62 | AS33: =AVERAGE(AP33:AR33) -> 50 | AT33: 75 | AU33: 83 | AV33: 83 | AW33: 50 | AX33: 53 | AY33: 48 | AZ33: =(AT33+AU33+AV33)/(AW33+AX33+AY33) -> 1.5960265 | BA33: =AVERAGE(AT33:AV33) -> 80.333333 | BB33: =BA33-AS33 -> 30.333333 | BC33: =AB33+AE33-AH33-AI33 -> 148 | BD33: =BC33/AS33 -> 2.96 | BE33: =BC33/G33 -> 0.24004751 | BF33: =A33 -> 蒙牛乳业
A34: 蒙牛乳业 | B34: 2024年报 | C34: 14.45 | D34: =C34*$B$2 -> 13.22464 | E34: 39.16 | F34: 10.6 | G34: =D34*E34 -> 517.8769 | H34: =C34/F34 -> 1.3632075 | I34: 0.509 | J34: =F34/F33-1 -> -0.058614565 | K34: =I34/C34 -> 0.035224913 | L34: =I34+F34*J34 -> -0.11231439 | M34: =W34/E34 -> 1.3942799 | N34: =L34/F34 -> -0.010595697 | O34: =U34/E34 -> 0.026813075 | P34: =D34*E34/W34 -> 9.484925 | Q34: 887 | R34: 536 | S34: 16 | T34: 2.25 | U34: 1.05 | V34: =U34/T34 -> 0.46666667 | W34: 54.6 | X34: 231 | Y34: 42 | Z34: 0 | AA34: 14.7 | AB34: 256 | AC34: 33 | AD34: 49 | AE34: 261 | AF34: 86 | AH34: 267 | AI34: 180 | AJ34: 1063 | AK34: 480 | AL34: 705 | AM34: 370 | AN34: =AJ34-AM34 -> 693 | AO34: 83 | AP34: 36 | AQ34: 39 | AR34: 49 | AS34: =AVERAGE(AP34:AR34) -> 41.333333 | AT34: 83 | AU34: 83 | AV34: 83 | AW34: 50 | AX34: 50 | AY34: 53 | AZ34: =(AT34+AU34+AV34)/(AW34+AX34+AY34) -> 1.627451 | BA34: =AVERAGE(AT34:AV34) -> 83 | BB34: =BA34-AS34 -> 41.666667 | BC34: =AB34+AE34-AH34-AI34 -> 70 | BD34: =BC34/AS34 -> 1.6935484 | BE34: =BC34/G34 -> 0.13516726 | BF34: =A34 -> 蒙牛乳业
A35: 长实集团 | B35: 2023年报 | C35: 31.7 | D35: =C35*$B$2 -> 29.01184 | E35: 35.11 | F35: 111 | G35: =D35*E35 -> 1018.6057 | H35: =C35/F35 -> 0.28558559 | I35: =1.62+0.43 -> 2.05 | J35: 0.033 | K35: =I35/C35 -> 0.06466877 | L35: =I35+F35*J35 -> 5.713 | M35: =W35/E35 -> 4.4146967 | N35: =L35/F35 -> 0.051468468 | O35: =U35/E35 -> 5.0128169 | P35: =D35*E35/W35 -> 6.5716497 | Q35: 710 | R35: 97 | S35: 178 | T35: 175 | U35: 176 | V35: =U35/T35 -> 1.0057143 | W35: 155 | X35: 0 | Y35: 250 | Z35: 0 | AA35: 16 | AB35: 425 | AC35: 15.5 | AD35: 1301 | AE35: 984 | AF35: 41.7 | AH35: 178 | AI35: 426 | AJ35: 5088 | AK35: 3994 | AL35: 3264 | AM35: 518 | AN35: =AJ35-AM35 -> 4570 | AO35: 3.78 | AP35: 43 | AQ35: 62 | AR35: 54 | AS35: =AVERAGE(AP35:AR35) -> 53 | AT35: 254 | AU35: 66 | AV35: 4 | AW35: 215 | AX35: 220 | AY35: 176 | AZ35: =(AT35+AU35+AV35)/(AW35+AX35+AY35) -> 0.53027823 | BA35: =AVERAGE(AT35:AV35) -> 108 | BB35: =BA35-AS35 -> 55 | BC35: =AB35+AE35-AH35-AI35 -> 805 | BD35: =BC35/AS35 -> 15.188679 | BE35: =BC35/G35 -> 0.79029599 | BF35: =A35 -> 长实集团
A36: 长实集团 | B36: 2024年报 | C36: 37 | D36: =C36*$B$2 -> 33.8624 | E36: 35 | F36: 113 | G36: =D36*E36 -> 1185.184 | H36: =C36/F36 -> 0.32743363 | I36: 1.74 | J36: =F36/F35-1 -> 0.018018018 | K36: =I36/C36 -> 0.047027027 | L36: =I36+F36*J36 -> 3.776036 | M36: =W36/E36 -> 3.9714286 | N36: =L36/F36 -> 0.033416248 | O36: =U36/E36 -> 3.9714286 | P36: =D36*E36/W36 -> 8.5265036 | Q36: 716 | R36: 88 | S36: 116 | T36: 137 | U36: 139 | V36: =U36/T36 -> 1.0145985 | W36: 139 | X36: 0 | Y36: 261 | Z36: 0 | AA36: 20 | AB36: 361 | AC36: 21 | AD36: 1298 | AE36: 975 | AF36: 37 | AH36: 111 | AI36: 462 | AJ36: 5017 | AK36: 4002 | AL36: 3258 | AM36: 413 | AN36: =AJ36-AM36 -> 4604 | AO36: 3.78 | AP36: 43 | AQ36: 62 | AR36: 54 | AS36: =AVERAGE(AP36:AR36) -> 53 | AT36: 254 | AU36: 66 | AV36: 4 | AW36: 215 | AX36: 220 | AY36: 176 | AZ36: =(AT36+AU36+AV36)/(AW36+AX36+AY36) -> 0.53027823 | BA36: =AVERAGE(AT36:AV36) -> 108 | BB36: =BA36-AS36 -> 55 | BC36: =AB36+AE36-AH36-AI36 -> 763 | BD36: =BC36/AS36 -> 14.396226 | BE36: =BC36/G36 -> 0.64378189 | BF36: =A36 -> 长实集团
A37: 长和 | B37: 2023年报 | C37: 51 | D37: =C37*$B$2 -> 46.6752 | E37: 38.3 | F37: 143.24 | G37: =D37*E37 -> 1787.6602 | H37: =C37/F37 -> 0.3560458 | I37: =1.775+0.756 -> 2.531 | J37: 0.03 | K37: =I37/C37 -> 0.049627451 | L37: =I37+F37*J37 -> 6.8282 | M37: =W37/E37 -> 6.1357702 | N37: =L37/F37 -> 0.047669645 | O37: =U37/E37 -> 6.1357702 | P37: =D37*E37/W37 -> 7.6070645 | Q37: 2756 | R37: 1057 | S37: 150 | T37: 302 | U37: 235 | V37: =U37/T37 -> 0.7781457 | W37: 235 | X37: 0 | Y37: 945 | Z37: 0 | AA37: 122 | AB37: 1273 | AE37: 3157 | AH37: 719 | AI37: 2711 | AJ37: 11600 | AK37: 6705 | AL37: 9203 | AM37: 1310 | AN37: =AJ37-AM37 -> 10290 | AO37: 514 | AP37: 217 | AQ37: 239 | AR37: 270 | AS37: =AVERAGE(AP37:AR37) -> 242 | AT37: 522 | AU37: 567 | AV37: 514 | AW37: 335 | AX37: 367 | AY37: 235 | AZ37: =(AT37+AU37+AV37)/(AW37+AX37+AY37) -> 1.7107791 | BA37: =AVERAGE(AT37:AV37) -> 534.33333 | BB37: =BA37-AS37 -> 292.33333 | BC37: =AB37+AE37-AH37-AI37 -> 1000 | BD37: =BC37/AS37 -> 4.1322314 | BE37: =BC37/G37 -> 0.55939044 | BF37: =A37 -> 长和
A38: 长江基建 | B38: 2023年报 | C38: 53 | D38: =C38*$B$2 -> 48.5056 | E38: 25.2 | F38: 52.86 | G38: =D38*E38 -> 1222.3411 | H38: =C38/F38 -> 1.0026485 | I38: =1.85+0.71 -> 2.56 | J38: 0.03 | K38: =I38/C38 -> 0.048301887 | L38: =I38+F38*J38 -> 4.1458 | M38: =W38/E38 -> 3.1746032 | N38: =L38/F38 -> 0.078429815 | O38: =U38/E38 -> 3.3730159 | P38: =D38*E38/W38 -> 15.279264 | Q38: 386 | S38: 23.2 | T38: 85 | U38: 85 | V38: =U38/T38 -> 1 | W38: 80 | X38: 0 | Y38: 43 | Z38: 0 | AA38: 7.7 | AB38: 136 | AE38: 1456 | AH38: 90 | AI38: 152 | AJ38: 1659 | AK38: 1333 | AL38: 1483 | AM38: 112 | AN38: =AJ38-AM38 -> 1547 | AO38: =38.5+24 -> 62.5 | AP38: 3.2 | AQ38: 4.7 | AR38: 3.6 | AS38: =AVERAGE(AP38:AR38) -> 3.8333333 | AT38: =31+43 -> 74 | AU38: =17+149 -> 166 | AV38: =24+38.5 -> 62.5 | AW38: 79.5 | AX38: 82 | AY38: 85 | AZ38: =(AT38+AU38+AV38)/(AW38+AX38+AY38) -> 1.2271805 | BA38: =AVERAGE(AT38:AV38) -> 100.83333 | BB38: =BA38-AS38 -> 97 | BC38: =AB38+AE38-AH38-AI38 -> 1350 | BD38: =BC38/AS38 -> 352.17391 | BE38: =BC38/G38 -> 1.104438 | BF38: =A38 -> 长江基建
A39: 电能实业 | B39: 2023年报 | C39: 50.7 | D39: =C39*$B$2 -> 46.40064 | E39: 21.31 | F39: 41.65 | G39: =D39*E39 -> 988.79764 | H39: =C39/F39 -> 1.2172869 | I39: =2.04+0.78 -> 2.82 | J39: 0.02 | K39: =I39/C39 -> 0.055621302 | L39: =I39+F39*J39 -> 3.653 | M39: =W39/E39 -> 2.8155795 | N39: =L39/F39 -> 0.087707083 | O39: =U39/E39 -> 2.8155795 | P39: =D39*E39/W39 -> 16.479961 | Q39: 12.92 | S39: 9.88 | T39: 60 | U39: 60 | V39: =U39/T39 -> 1 | W39: 60 | X39: 0 | Y39: 0 | Z39: 0 | AA39: 1.4 | AB39: 42 | AE39: 913 | AH39: 0 | AI39: 31 | AJ39: 957 | AK39: 888 | AL39: 906 | AM39: 41 | AN39: =AJ39-AM39 -> 916 | AO39: =11.4+46 -> 57.4 | AP39: 0 | AQ39: 0 | AR39: 0 | AS39: =AVERAGE(AP39:AR39) -> 0 | AT39: =9.4+59 -> 68.4 | AU39: =7.7+40 -> 47.7 | AV39: =11.4+46 -> 57.4 | AW39: 61 | AX39: 56 | AY39: 60 | AZ39: =(AT39+AU39+AV39)/(AW39+AX39+AY39) -> 0.98022599 | BA39: =AVERAGE(AT39:AV39) -> 57.833333 | BB39: =BA39-AS39 -> 57.833333 | BC39: =AB39+AE39-AH39-AI39 -> 924 | BE39: =BC39/G39 -> 0.93446825 | BF39: =A39 -> 电能实业
A40: 白云山 | B40: 2023年报 | C40: 16.94 | D40: =C40*$B$2 -> 15.503488 | E40: 16.26 | F40: 24.9 | G40: =D40*E40 -> 252.08671 | H40: =C40/F40 -> 0.68032129 | I40: =0.749/B2 -> 0.81840035 | J40: 0.1 | K40: =I40/C40 -> 0.048311709 | L40: =I40+F40*J40 -> 3.3084003 | M40: =W40/E40 -> 2.5215252 | N40: =L40/F40 -> 0.13286748 | O40: =U40/E40 -> 2.5215252 | P40: =D40*E40/W40 -> 6.1484565 | Q40: 755 | R40: 617 | S40: 50 | T40: 43 | U40: 41 | V40: =U40/T40 -> 0.95348837 | W40: 41 | X40: 61 | Y40: 24 | Z40: 7.8 | AA40: 4.7 | AB40: 213 | AC40: 160 | AD40: 115 | AE40: 19 | AF40: 157 | AH40: 78 | AI40: 39 | AJ40: 786 | AK40: 367 | AL40: 226 | AM40: 389 | AN40: =AJ40-AM40 -> 397 | AO40: 41 | AP40: 16 | AQ40: 14 | AR40: 13 | AS40: =AVERAGE(AP40:AR40) -> 14.333333 | AT40: 57 | AU40: 70 | AV40: 41 | AW40: 43 | AX40: 43 | AY40: 37 | AZ40: =(AT40+AU40+AV40)/(AW40+AX40+AY40) -> 1.3658537 | BA40: =AVERAGE(AT40:AV40) -> 56 | BB40: =BA40-AS40 -> 41.666667 | BC40: =AB40+AE40-AH40-AI40 -> 115 | BD40: =BC40/AS40 -> 8.0232558 | BE40: =BC40/G40 -> 0.45619223 | BF40: =A40 -> 白云山
...
